{
 "cells": [
  {
   "cell_type": "markdown",
   "id": "7b3652fa",
   "metadata": {},
   "source": [
    "**Exception Handling in Python**\n",
    "\n",
    "Exceptions are the alerts when something unexpected happends while running a program. It could be a mistake in the code, or a situation that was not planned for. \n",
    "\n",
    "There are some differents between error and exceptions. \n",
    "* Error is usually a big problem that come from computer or the system, it often make the program stop working completely.\n",
    "* Execptions are like some issues that we can control. It happen because of something we did in our code, and it can be fixed so the program keeps going."
   ]
  },
  {
   "cell_type": "markdown",
   "id": "67ef6ae6",
   "metadata": {},
   "source": [
    "# Errors Type in Python"
   ]
  },
  {
   "cell_type": "code",
   "execution_count": 1,
   "id": "73e49fda",
   "metadata": {},
   "outputs": [
    {
     "ename": "ZeroDivisionError",
     "evalue": "division by zero",
     "output_type": "error",
     "traceback": [
      "\u001b[1;31m---------------------------------------------------------------------------\u001b[0m",
      "\u001b[1;31mZeroDivisionError\u001b[0m                         Traceback (most recent call last)",
      "Cell \u001b[1;32mIn[1], line 1\u001b[0m\n\u001b[1;32m----> 1\u001b[0m \u001b[38;5;241m1\u001b[39m\u001b[38;5;241m/\u001b[39m\u001b[38;5;241m0\u001b[39m\n",
      "\u001b[1;31mZeroDivisionError\u001b[0m: division by zero"
     ]
    }
   ],
   "source": [
    "#ZeroDivisionError\n",
    "1/0"
   ]
  },
  {
   "cell_type": "code",
   "execution_count": null,
   "id": "0eae6053",
   "metadata": {},
   "outputs": [],
   "source": []
  },
  {
   "cell_type": "code",
   "execution_count": 2,
   "id": "4fcd6857",
   "metadata": {},
   "outputs": [
    {
     "ename": "NameError",
     "evalue": "name 'a' is not defined",
     "output_type": "error",
     "traceback": [
      "\u001b[1;31m---------------------------------------------------------------------------\u001b[0m",
      "\u001b[1;31mNameError\u001b[0m                                 Traceback (most recent call last)",
      "Cell \u001b[1;32mIn[2], line 1\u001b[0m\n\u001b[1;32m----> 1\u001b[0m y \u001b[38;5;241m=\u001b[39m a \u001b[38;5;241m+\u001b[39m \u001b[38;5;241m5\u001b[39m\n",
      "\u001b[1;31mNameError\u001b[0m: name 'a' is not defined"
     ]
    }
   ],
   "source": [
    "#Name error, we try to use variable that not defined before\n",
    "y = a + 5"
   ]
  },
  {
   "cell_type": "code",
   "execution_count": 9,
   "id": "8795fc51",
   "metadata": {},
   "outputs": [
    {
     "ename": "ValueError",
     "evalue": "invalid literal for int() with base 10: 'abc'",
     "output_type": "error",
     "traceback": [
      "\u001b[1;31m---------------------------------------------------------------------------\u001b[0m",
      "\u001b[1;31mValueError\u001b[0m                                Traceback (most recent call last)",
      "Cell \u001b[1;32mIn[9], line 2\u001b[0m\n\u001b[0;32m      1\u001b[0m \u001b[38;5;66;03m#Value error\u001b[39;00m\n\u001b[1;32m----> 2\u001b[0m num \u001b[38;5;241m=\u001b[39m \u001b[38;5;28mint\u001b[39m(\u001b[38;5;124m\"\u001b[39m\u001b[38;5;124mabc\u001b[39m\u001b[38;5;124m\"\u001b[39m)\n",
      "\u001b[1;31mValueError\u001b[0m: invalid literal for int() with base 10: 'abc'"
     ]
    }
   ],
   "source": [
    "#Value error, inappropiate value is used within the code\n",
    "num = int(\"abc\")"
   ]
  },
  {
   "cell_type": "code",
   "execution_count": 11,
   "id": "ff19ab5a",
   "metadata": {},
   "outputs": [
    {
     "ename": "FileNotFoundError",
     "evalue": "[Errno 2] No such file or directory: 'yes.txt'",
     "output_type": "error",
     "traceback": [
      "\u001b[1;31m---------------------------------------------------------------------------\u001b[0m",
      "\u001b[1;31mFileNotFoundError\u001b[0m                         Traceback (most recent call last)",
      "Cell \u001b[1;32mIn[11], line 2\u001b[0m\n\u001b[0;32m      1\u001b[0m \u001b[38;5;66;03m#FileNotFoundError, when acessing a file that not exist\u001b[39;00m\n\u001b[1;32m----> 2\u001b[0m \u001b[38;5;28;01mwith\u001b[39;00m \u001b[38;5;28mopen\u001b[39m(\u001b[38;5;124m\"\u001b[39m\u001b[38;5;124myes.txt\u001b[39m\u001b[38;5;124m\"\u001b[39m,\u001b[38;5;124m\"\u001b[39m\u001b[38;5;124mr\u001b[39m\u001b[38;5;124m\"\u001b[39m) \u001b[38;5;28;01mas\u001b[39;00m file:\n\u001b[0;32m      3\u001b[0m     content \u001b[38;5;241m=\u001b[39m file\u001b[38;5;241m.\u001b[39mread()\n",
      "File \u001b[1;32m~\\anaconda3\\Lib\\site-packages\\IPython\\core\\interactiveshell.py:284\u001b[0m, in \u001b[0;36m_modified_open\u001b[1;34m(file, *args, **kwargs)\u001b[0m\n\u001b[0;32m    277\u001b[0m \u001b[38;5;28;01mif\u001b[39;00m file \u001b[38;5;129;01min\u001b[39;00m {\u001b[38;5;241m0\u001b[39m, \u001b[38;5;241m1\u001b[39m, \u001b[38;5;241m2\u001b[39m}:\n\u001b[0;32m    278\u001b[0m     \u001b[38;5;28;01mraise\u001b[39;00m \u001b[38;5;167;01mValueError\u001b[39;00m(\n\u001b[0;32m    279\u001b[0m         \u001b[38;5;124mf\u001b[39m\u001b[38;5;124m\"\u001b[39m\u001b[38;5;124mIPython won\u001b[39m\u001b[38;5;124m'\u001b[39m\u001b[38;5;124mt let you open fd=\u001b[39m\u001b[38;5;132;01m{\u001b[39;00mfile\u001b[38;5;132;01m}\u001b[39;00m\u001b[38;5;124m by default \u001b[39m\u001b[38;5;124m\"\u001b[39m\n\u001b[0;32m    280\u001b[0m         \u001b[38;5;124m\"\u001b[39m\u001b[38;5;124mas it is likely to crash IPython. If you know what you are doing, \u001b[39m\u001b[38;5;124m\"\u001b[39m\n\u001b[0;32m    281\u001b[0m         \u001b[38;5;124m\"\u001b[39m\u001b[38;5;124myou can use builtins\u001b[39m\u001b[38;5;124m'\u001b[39m\u001b[38;5;124m open.\u001b[39m\u001b[38;5;124m\"\u001b[39m\n\u001b[0;32m    282\u001b[0m     )\n\u001b[1;32m--> 284\u001b[0m \u001b[38;5;28;01mreturn\u001b[39;00m io_open(file, \u001b[38;5;241m*\u001b[39margs, \u001b[38;5;241m*\u001b[39m\u001b[38;5;241m*\u001b[39mkwargs)\n",
      "\u001b[1;31mFileNotFoundError\u001b[0m: [Errno 2] No such file or directory: 'yes.txt'"
     ]
    }
   ],
   "source": [
    "#FileNotFoundError, when acessing a file that not exist\n",
    "with open(\"yes.txt\",\"r\") as file:\n",
    "    content = file.read()"
   ]
  },
  {
   "cell_type": "code",
   "execution_count": 7,
   "id": "e5cebcec",
   "metadata": {},
   "outputs": [
    {
     "ename": "IndexError",
     "evalue": "list index out of range",
     "output_type": "error",
     "traceback": [
      "\u001b[1;31m---------------------------------------------------------------------------\u001b[0m",
      "\u001b[1;31mIndexError\u001b[0m                                Traceback (most recent call last)",
      "Cell \u001b[1;32mIn[7], line 3\u001b[0m\n\u001b[0;32m      1\u001b[0m \u001b[38;5;66;03m#Index error, we try to acces data from a list using index that doesnt exist\u001b[39;00m\n\u001b[0;32m      2\u001b[0m a \u001b[38;5;241m=\u001b[39m [\u001b[38;5;241m1\u001b[39m,\u001b[38;5;241m2\u001b[39m,\u001b[38;5;241m3\u001b[39m]\n\u001b[1;32m----> 3\u001b[0m a[\u001b[38;5;241m10\u001b[39m]\n",
      "\u001b[1;31mIndexError\u001b[0m: list index out of range"
     ]
    }
   ],
   "source": [
    "#Index error, we try to acces data from a list using index that doesnt exist\n",
    "a = [1,2,3]\n",
    "a[10]"
   ]
  },
  {
   "cell_type": "code",
   "execution_count": 13,
   "id": "7b6750e9",
   "metadata": {},
   "outputs": [
    {
     "ename": "KeyError",
     "evalue": "'hoo'",
     "output_type": "error",
     "traceback": [
      "\u001b[1;31m---------------------------------------------------------------------------\u001b[0m",
      "\u001b[1;31mKeyError\u001b[0m                                  Traceback (most recent call last)",
      "Cell \u001b[1;32mIn[13], line 3\u001b[0m\n\u001b[0;32m      1\u001b[0m \u001b[38;5;66;03m#Key error, acces non existent key in a dictionary\u001b[39;00m\n\u001b[0;32m      2\u001b[0m dic \u001b[38;5;241m=\u001b[39m {\u001b[38;5;124m'\u001b[39m\u001b[38;5;124mhi\u001b[39m\u001b[38;5;124m'\u001b[39m:\u001b[38;5;124m'\u001b[39m\u001b[38;5;124m5\u001b[39m\u001b[38;5;124m'\u001b[39m,\u001b[38;5;124m'\u001b[39m\u001b[38;5;124mhel\u001b[39m\u001b[38;5;124m'\u001b[39m:\u001b[38;5;241m7\u001b[39m}\n\u001b[1;32m----> 3\u001b[0m dic[\u001b[38;5;124m'\u001b[39m\u001b[38;5;124mhoo\u001b[39m\u001b[38;5;124m'\u001b[39m]\n",
      "\u001b[1;31mKeyError\u001b[0m: 'hoo'"
     ]
    }
   ],
   "source": [
    "#Key error, acces non existent key in a dictionary\n",
    "dic = {'hi':'5','hel':7}\n",
    "dic['hoo']"
   ]
  },
  {
   "cell_type": "code",
   "execution_count": 14,
   "id": "e608c69e",
   "metadata": {},
   "outputs": [
    {
     "ename": "TypeError",
     "evalue": "can only concatenate str (not \"int\") to str",
     "output_type": "error",
     "traceback": [
      "\u001b[1;31m---------------------------------------------------------------------------\u001b[0m",
      "\u001b[1;31mTypeError\u001b[0m                                 Traceback (most recent call last)",
      "Cell \u001b[1;32mIn[14], line 2\u001b[0m\n\u001b[0;32m      1\u001b[0m \u001b[38;5;66;03m#type error, when an object is used in an incompatible manner\u001b[39;00m\n\u001b[1;32m----> 2\u001b[0m res \u001b[38;5;241m=\u001b[39m \u001b[38;5;124m'\u001b[39m\u001b[38;5;124mhello\u001b[39m\u001b[38;5;124m'\u001b[39m \u001b[38;5;241m+\u001b[39m \u001b[38;5;241m5\u001b[39m\n\u001b[0;32m      3\u001b[0m res\n",
      "\u001b[1;31mTypeError\u001b[0m: can only concatenate str (not \"int\") to str"
     ]
    }
   ],
   "source": [
    "#type error, when an object is used in an incompatible manner\n",
    "res = 'hello' + 5\n",
    "res"
   ]
  },
  {
   "cell_type": "code",
   "execution_count": 15,
   "id": "0e16ce6b",
   "metadata": {},
   "outputs": [
    {
     "ename": "AttributeError",
     "evalue": "'str' object has no attribute 'sum'",
     "output_type": "error",
     "traceback": [
      "\u001b[1;31m---------------------------------------------------------------------------\u001b[0m",
      "\u001b[1;31mAttributeError\u001b[0m                            Traceback (most recent call last)",
      "Cell \u001b[1;32mIn[15], line 5\u001b[0m\n\u001b[0;32m      1\u001b[0m \u001b[38;5;66;03m#AttributeError, when an attribute or method is accesed on an object that\u001b[39;00m\n\u001b[0;32m      2\u001b[0m \u001b[38;5;66;03m#doesnt possess that specific attribute or method\u001b[39;00m\n\u001b[0;32m      4\u001b[0m text \u001b[38;5;241m=\u001b[39m \u001b[38;5;124m'\u001b[39m\u001b[38;5;124mexample\u001b[39m\u001b[38;5;124m'\u001b[39m\n\u001b[1;32m----> 5\u001b[0m mis \u001b[38;5;241m=\u001b[39m text\u001b[38;5;241m.\u001b[39msum()\n",
      "\u001b[1;31mAttributeError\u001b[0m: 'str' object has no attribute 'sum'"
     ]
    }
   ],
   "source": [
    "#AttributeError, when an attribute or method is accesed on an object that\n",
    "#doesnt possess that specific attribute or method\n",
    "\n",
    "text = 'example'\n",
    "mis = text.sum()"
   ]
  },
  {
   "cell_type": "markdown",
   "id": "c4309cc3",
   "metadata": {},
   "source": [
    "# Exeption Handling"
   ]
  },
  {
   "cell_type": "code",
   "execution_count": 6,
   "id": "c288f647",
   "metadata": {},
   "outputs": [
    {
     "name": "stdout",
     "output_type": "stream",
     "text": [
      "please enter 1st numberal\n",
      "You did not entered a number\n",
      "Operation Complete\n"
     ]
    }
   ],
   "source": [
    "\n",
    "try:\n",
    "    a = int(input(\"please enter 1st number\"))\n",
    "    b = int(input(\"please enter 2nd number\"))\n",
    "    c = a/b\n",
    "except ZeroDivisionError:\n",
    "    print (\"The number you provided cant be divide because it is undefined operation\")\n",
    "except ValueError:\n",
    "    print (\"You did not entered a number\")\n",
    "except:\n",
    "    print (\"Something Went Wrong\")\n",
    "else:\n",
    "    print (\"Success! The result is:\",c)\n",
    "finally:\n",
    "    print (\"Operation Complete\")"
   ]
  },
  {
   "cell_type": "markdown",
   "id": "6edf9969",
   "metadata": {},
   "source": [
    "Notes!\n",
    "\n",
    "The ammountand type of exeption depends on our prediction what human's errors that the inputers can be did. There are like a messages depend on the exception, and our goals is to let the user know what is they wrong that the program can not be run well.\n",
    "\n",
    "Other arguments :\n",
    "* Else, allows one to check if there was no exception at all of their program. This is useful when we want execute something that no has errors at all.\n",
    "* Finally, sllows us to always execute something, even though there is no errors or not. This indicates the end validation of exeption handling"
   ]
  },
  {
   "cell_type": "code",
   "execution_count": null,
   "id": "2e7f8859",
   "metadata": {},
   "outputs": [],
   "source": []
  }
 ],
 "metadata": {
  "kernelspec": {
   "display_name": "Python 3 (ipykernel)",
   "language": "python",
   "name": "python3"
  },
  "language_info": {
   "codemirror_mode": {
    "name": "ipython",
    "version": 3
   },
   "file_extension": ".py",
   "mimetype": "text/x-python",
   "name": "python",
   "nbconvert_exporter": "python",
   "pygments_lexer": "ipython3",
   "version": "3.11.4"
  }
 },
 "nbformat": 4,
 "nbformat_minor": 5
}
